2025-06-25 11:37:28 - __main__ - INFO - Testing logging system
2025-06-25 11:38:22 - utils.config.Config - INFO - Initializing configuration with file: config.json
2025-06-25 11:38:22 - utils.db_manager.DatabaseManager - INFO - Initializing DatabaseManager with database: C:\Users\pikmi\Downloads\mangascraper\manga_collection.db
2025-06-25 11:38:22 - utils.db_manager.DatabaseManager - INFO - Database initialized successfully
2025-06-25 11:38:22 - scraper.webtoon_client.WebtoonClient - INFO - WebtoonClient initialized
2025-06-25 11:38:22 - scraper.downloader.ImageDownloader - INFO - ImageDownloader initialized
2025-06-25 11:38:22 - scraper.comment_analyzer.CommentAnalyzer - INFO - Downloading NLTK package: vader_lexicon
2025-06-25 11:38:25 - scraper.comment_analyzer.CommentAnalyzer - INFO - CommentAnalyzer initialized
2025-06-25 11:39:16 - utils.config.Config - INFO - Initializing configuration with file: config.json
2025-06-25 11:39:16 - utils.db_manager.DatabaseManager - INFO - Initializing DatabaseManager with database: C:\Users\pikmi\Downloads\mangascraper\manga_collection.db
2025-06-25 11:39:16 - utils.db_manager.DatabaseManager - INFO - Database initialized successfully
2025-06-25 11:39:16 - scraper.webtoon_client.WebtoonClient - INFO - WebtoonClient initialized
2025-06-25 11:39:16 - scraper.downloader.ImageDownloader - INFO - ImageDownloader initialized
2025-06-25 11:39:16 - scraper.comment_analyzer.CommentAnalyzer - INFO - Downloading NLTK package: vader_lexicon
2025-06-25 11:39:17 - scraper.comment_analyzer.CommentAnalyzer - INFO - CommentAnalyzer initialized
2025-06-25 11:41:32 - scraper.downloader.ImageDownloader - INFO - Saved download queue with 1 chapters
2025-06-25 11:41:34 - urllib3.connectionpool - WARNING - Connection pool is full, discarding connection: webtoon-phinf.pstatic.net. Connection pool size: 10
2025-06-25 11:41:34 - urllib3.connectionpool - WARNING - Connection pool is full, discarding connection: webtoon-phinf.pstatic.net. Connection pool size: 10
2025-06-25 11:41:34 - urllib3.connectionpool - WARNING - Connection pool is full, discarding connection: webtoon-phinf.pstatic.net. Connection pool size: 10
2025-06-25 11:41:34 - urllib3.connectionpool - WARNING - Connection pool is full, discarding connection: webtoon-phinf.pstatic.net. Connection pool size: 10
2025-06-25 11:41:34 - urllib3.connectionpool - WARNING - Connection pool is full, discarding connection: webtoon-phinf.pstatic.net. Connection pool size: 10
2025-06-25 11:41:34 - urllib3.connectionpool - WARNING - Connection pool is full, discarding connection: webtoon-phinf.pstatic.net. Connection pool size: 10
2025-06-25 11:41:34 - urllib3.connectionpool - WARNING - Connection pool is full, discarding connection: webtoon-phinf.pstatic.net. Connection pool size: 10
2025-06-25 11:41:34 - urllib3.connectionpool - WARNING - Connection pool is full, discarding connection: webtoon-phinf.pstatic.net. Connection pool size: 10
2025-06-25 11:41:34 - urllib3.connectionpool - WARNING - Connection pool is full, discarding connection: webtoon-phinf.pstatic.net. Connection pool size: 10
2025-06-25 11:41:34 - urllib3.connectionpool - WARNING - Connection pool is full, discarding connection: webtoon-phinf.pstatic.net. Connection pool size: 10
2025-06-25 11:41:34 - scraper.downloader.ImageDownloader - INFO - Downloaded 100/100 images for Episode 45
2025-06-25 11:41:34 - scraper.downloader.ImageDownloader - INFO - Cleared download queue
2025-06-25 11:41:34 - scraper.downloader.ImageDownloader - INFO - All 1 chapters downloaded successfully!
2025-06-25 11:43:48 - scraper.webtoon_client.WebtoonClient - INFO - WebtoonClient initialized
2025-06-25 11:44:06 - scraper.webtoon_client.WebtoonClient - INFO - WebtoonClient initialized
2025-06-25 11:44:30 - scraper.webtoon_client.WebtoonClient - INFO - WebtoonClient initialized
2025-06-25 11:44:30 - scraper.parsers.WebtoonParser - INFO - Fetching chapter links from: https://www.webtoons.com/en/romance/lore-olympus/list?title_no=1320
2025-06-25 11:45:02 - scraper.webtoon_client.WebtoonClient - INFO - WebtoonClient initialized
2025-06-25 11:45:37 - scraper.webtoon_client.WebtoonClient - INFO - WebtoonClient initialized
2025-06-25 11:45:52 - scraper.webtoon_client.WebtoonClient - INFO - WebtoonClient initialized
2025-06-25 11:53:06 - utils.config.Config - INFO - Initializing configuration with file: config.json
2025-06-25 11:53:06 - utils.db_manager.DatabaseManager - INFO - Initializing DatabaseManager with database: C:\Users\pikmi\Downloads\mangascraper\manga_collection.db
2025-06-25 11:53:06 - utils.db_manager.DatabaseManager - INFO - Database initialized successfully
2025-06-25 11:53:06 - scraper.webtoon_client.WebtoonClient - INFO - WebtoonClient initialized
2025-06-25 11:53:06 - scraper.downloader.ImageDownloader - INFO - ImageDownloader initialized
2025-06-25 11:53:06 - scraper.comment_analyzer.CommentAnalyzer - INFO - Downloading NLTK package: vader_lexicon
2025-06-25 11:53:06 - scraper.comment_analyzer.CommentAnalyzer - INFO - CommentAnalyzer initialized
2025-06-25 11:53:33 - utils.config.Config - INFO - Initializing configuration with file: config.json
2025-06-25 11:53:33 - utils.db_manager.DatabaseManager - INFO - Initializing DatabaseManager with database: C:\Users\pikmi\Downloads\mangascraper\manga_collection.db
2025-06-25 11:53:33 - utils.db_manager.DatabaseManager - INFO - Database initialized successfully
2025-06-25 11:53:33 - scraper.webtoon_client.WebtoonClient - INFO - WebtoonClient initialized
2025-06-25 11:53:33 - scraper.downloader.ImageDownloader - INFO - ImageDownloader initialized
2025-06-25 11:53:33 - scraper.comment_analyzer.CommentAnalyzer - INFO - Downloading NLTK package: vader_lexicon
2025-06-25 11:53:33 - scraper.comment_analyzer.CommentAnalyzer - INFO - CommentAnalyzer initialized
2025-06-25 11:53:43 - scraper.downloader.ImageDownloader - INFO - Saved download queue with 1 chapters
2025-06-25 11:53:45 - urllib3.connectionpool - WARNING - Connection pool is full, discarding connection: webtoon-phinf.pstatic.net. Connection pool size: 10
2025-06-25 11:53:45 - urllib3.connectionpool - WARNING - Connection pool is full, discarding connection: webtoon-phinf.pstatic.net. Connection pool size: 10
2025-06-25 11:53:45 - urllib3.connectionpool - WARNING - Connection pool is full, discarding connection: webtoon-phinf.pstatic.net. Connection pool size: 10
2025-06-25 11:53:45 - urllib3.connectionpool - WARNING - Connection pool is full, discarding connection: webtoon-phinf.pstatic.net. Connection pool size: 10
2025-06-25 11:53:45 - urllib3.connectionpool - WARNING - Connection pool is full, discarding connection: webtoon-phinf.pstatic.net. Connection pool size: 10
2025-06-25 11:53:45 - urllib3.connectionpool - WARNING - Connection pool is full, discarding connection: webtoon-phinf.pstatic.net. Connection pool size: 10
2025-06-25 11:53:45 - urllib3.connectionpool - WARNING - Connection pool is full, discarding connection: webtoon-phinf.pstatic.net. Connection pool size: 10
2025-06-25 11:53:45 - urllib3.connectionpool - WARNING - Connection pool is full, discarding connection: webtoon-phinf.pstatic.net. Connection pool size: 10
2025-06-25 11:53:45 - urllib3.connectionpool - WARNING - Connection pool is full, discarding connection: webtoon-phinf.pstatic.net. Connection pool size: 10
2025-06-25 11:53:45 - urllib3.connectionpool - WARNING - Connection pool is full, discarding connection: webtoon-phinf.pstatic.net. Connection pool size: 10
2025-06-25 11:53:45 - scraper.downloader.ImageDownloader - INFO - Downloaded 100/100 images for Episode 45
2025-06-25 11:53:45 - scraper.downloader.ImageDownloader - INFO - Cleared download queue
2025-06-25 11:53:45 - scraper.downloader.ImageDownloader - INFO - All 1 chapters downloaded successfully!
2025-06-26 11:59:27 - manga_scraper - INFO - config.py:144 - Configuration validated successfully for Webtoon Scraper v2.0.0
2025-06-26 11:59:27 - __main__ - INFO - error_handling_improvements.py:132 - Starting error handling demonstration
2025-06-26 11:59:27 - __main__ - INFO - error_handling_improvements.py:39 - === NEW ERROR HANDLING (AFTER) ===
2025-06-26 11:59:27 - __main__ - ERROR - logger.py:178 - Network request failed: ConnectionError: HTTPSConnectionPool(host='nonexistent-website-12345.com', port=443): Max retries exceeded with url: / (Caused by NameResolutionError("<urllib3.connection.HTTPSConnection object at 0x000002B1999A1250>: Failed to resolve 'nonexistent-website-12345.com' ([Errno 11001] getaddrinfo failed)"))
Traceback (most recent call last):
  File "C:\Users\pikmi\AppData\Local\Packages\PythonSoftwareFoundation.Python.3.11_qbz5n2kfra8p0\LocalCache\local-packages\Python311\site-packages\urllib3\connection.py", line 198, in _new_conn
    sock = connection.create_connection(
           ^^^^^^^^^^^^^^^^^^^^^^^^^^^^^
  File "C:\Users\pikmi\AppData\Local\Packages\PythonSoftwareFoundation.Python.3.11_qbz5n2kfra8p0\LocalCache\local-packages\Python311\site-packages\urllib3\util\connection.py", line 60, in create_connection
    for res in socket.getaddrinfo(host, port, family, socket.SOCK_STREAM):
               ^^^^^^^^^^^^^^^^^^^^^^^^^^^^^^^^^^^^^^^^^^^^^^^^^^^^^^^^^^
  File "C:\Program Files\WindowsApps\PythonSoftwareFoundation.Python.3.11_3.11.2544.0_x64__qbz5n2kfra8p0\Lib\socket.py", line 962, in getaddrinfo
    for res in _socket.getaddrinfo(host, port, family, type, proto, flags):
               ^^^^^^^^^^^^^^^^^^^^^^^^^^^^^^^^^^^^^^^^^^^^^^^^^^^^^^^^^^^
socket.gaierror: [Errno 11001] getaddrinfo failed

The above exception was the direct cause of the following exception:

Traceback (most recent call last):
  File "C:\Users\pikmi\AppData\Local\Packages\PythonSoftwareFoundation.Python.3.11_qbz5n2kfra8p0\LocalCache\local-packages\Python311\site-packages\urllib3\connectionpool.py", line 787, in urlopen
    response = self._make_request(
               ^^^^^^^^^^^^^^^^^^^
  File "C:\Users\pikmi\AppData\Local\Packages\PythonSoftwareFoundation.Python.3.11_qbz5n2kfra8p0\LocalCache\local-packages\Python311\site-packages\urllib3\connectionpool.py", line 488, in _make_request
    raise new_e
  File "C:\Users\pikmi\AppData\Local\Packages\PythonSoftwareFoundation.Python.3.11_qbz5n2kfra8p0\LocalCache\local-packages\Python311\site-packages\urllib3\connectionpool.py", line 464, in _make_request
    self._validate_conn(conn)
  File "C:\Users\pikmi\AppData\Local\Packages\PythonSoftwareFoundation.Python.3.11_qbz5n2kfra8p0\LocalCache\local-packages\Python311\site-packages\urllib3\connectionpool.py", line 1093, in _validate_conn
    conn.connect()
  File "C:\Users\pikmi\AppData\Local\Packages\PythonSoftwareFoundation.Python.3.11_qbz5n2kfra8p0\LocalCache\local-packages\Python311\site-packages\urllib3\connection.py", line 704, in connect
    self.sock = sock = self._new_conn()
                       ^^^^^^^^^^^^^^^^
  File "C:\Users\pikmi\AppData\Local\Packages\PythonSoftwareFoundation.Python.3.11_qbz5n2kfra8p0\LocalCache\local-packages\Python311\site-packages\urllib3\connection.py", line 205, in _new_conn
    raise NameResolutionError(self.host, self, e) from e
urllib3.exceptions.NameResolutionError: <urllib3.connection.HTTPSConnection object at 0x000002B1999A1250>: Failed to resolve 'nonexistent-website-12345.com' ([Errno 11001] getaddrinfo failed)

The above exception was the direct cause of the following exception:

Traceback (most recent call last):
  File "C:\Users\pikmi\AppData\Local\Packages\PythonSoftwareFoundation.Python.3.11_qbz5n2kfra8p0\LocalCache\local-packages\Python311\site-packages\requests\adapters.py", line 486, in send
    resp = conn.urlopen(
           ^^^^^^^^^^^^^
  File "C:\Users\pikmi\AppData\Local\Packages\PythonSoftwareFoundation.Python.3.11_qbz5n2kfra8p0\LocalCache\local-packages\Python311\site-packages\urllib3\connectionpool.py", line 841, in urlopen
    retries = retries.increment(
              ^^^^^^^^^^^^^^^^^^
  File "C:\Users\pikmi\AppData\Local\Packages\PythonSoftwareFoundation.Python.3.11_qbz5n2kfra8p0\LocalCache\local-packages\Python311\site-packages\urllib3\util\retry.py", line 519, in increment
    raise MaxRetryError(_pool, url, reason) from reason  # type: ignore[arg-type]
    ^^^^^^^^^^^^^^^^^^^^^^^^^^^^^^^^^^^^^^^^^^^^^^^^^^^
urllib3.exceptions.MaxRetryError: HTTPSConnectionPool(host='nonexistent-website-12345.com', port=443): Max retries exceeded with url: / (Caused by NameResolutionError("<urllib3.connection.HTTPSConnection object at 0x000002B1999A1250>: Failed to resolve 'nonexistent-website-12345.com' ([Errno 11001] getaddrinfo failed)"))

During handling of the above exception, another exception occurred:

Traceback (most recent call last):
  File "F:\Documents\mangascraper1915\error_handling_improvements.py", line 44, in demonstrate_new_error_handling
    response = requests.get("https://nonexistent-website-12345.com", timeout=5)
               ^^^^^^^^^^^^^^^^^^^^^^^^^^^^^^^^^^^^^^^^^^^^^^^^^^^^^^^^^^^^^^^^
  File "C:\Users\pikmi\AppData\Local\Packages\PythonSoftwareFoundation.Python.3.11_qbz5n2kfra8p0\LocalCache\local-packages\Python311\site-packages\requests\api.py", line 73, in get
    return request("get", url, params=params, **kwargs)
           ^^^^^^^^^^^^^^^^^^^^^^^^^^^^^^^^^^^^^^^^^^^^
  File "C:\Users\pikmi\AppData\Local\Packages\PythonSoftwareFoundation.Python.3.11_qbz5n2kfra8p0\LocalCache\local-packages\Python311\site-packages\requests\api.py", line 59, in request
    return session.request(method=method, url=url, **kwargs)
           ^^^^^^^^^^^^^^^^^^^^^^^^^^^^^^^^^^^^^^^^^^^^^^^^^
  File "C:\Users\pikmi\AppData\Local\Packages\PythonSoftwareFoundation.Python.3.11_qbz5n2kfra8p0\LocalCache\local-packages\Python311\site-packages\requests\sessions.py", line 589, in request
    resp = self.send(prep, **send_kwargs)
           ^^^^^^^^^^^^^^^^^^^^^^^^^^^^^^
  File "C:\Users\pikmi\AppData\Local\Packages\PythonSoftwareFoundation.Python.3.11_qbz5n2kfra8p0\LocalCache\local-packages\Python311\site-packages\requests\sessions.py", line 703, in send
    r = adapter.send(request, **kwargs)
        ^^^^^^^^^^^^^^^^^^^^^^^^^^^^^^^
  File "C:\Users\pikmi\AppData\Local\Packages\PythonSoftwareFoundation.Python.3.11_qbz5n2kfra8p0\LocalCache\local-packages\Python311\site-packages\requests\adapters.py", line 519, in send
    raise ConnectionError(e, request=request)
requests.exceptions.ConnectionError: HTTPSConnectionPool(host='nonexistent-website-12345.com', port=443): Max retries exceeded with url: / (Caused by NameResolutionError("<urllib3.connection.HTTPSConnection object at 0x000002B1999A1250>: Failed to resolve 'nonexistent-website-12345.com' ([Errno 11001] getaddrinfo failed)"))
2025-06-26 11:59:27 - __main__ - INFO - error_handling_improvements.py:142 - Caught custom exception: Failed to fetch URL: HTTPSConnectionPool(host='nonexistent-website-12345.com', port=443): Max retries exceeded with url: / (Caused by NameResolutionError("<urllib3.connection.HTTPSConnection object at 0x000002B1999A1250>: Failed to resolve 'nonexistent-website-12345.com' ([Errno 11001] getaddrinfo failed)"))
2025-06-26 11:59:27 - __main__ - INFO - error_handling_improvements.py:60 - === DECORATOR ERROR HANDLING ===
2025-06-26 11:59:27 - __main__ - ERROR - logger.py:178 - Error in decorated function: ZeroDivisionError: division by zero
Traceback (most recent call last):
  File "F:\Documents\mangascraper1915\utils\logger.py", line 195, in wrapper
    return func(*args, **kwargs)
           ^^^^^^^^^^^^^^^^^^^^^
  File "F:\Documents\mangascraper1915\error_handling_improvements.py", line 63, in demonstrate_decorator_error_handling
    result = 1 / 0
             ~~^~~
ZeroDivisionError: division by zero
2025-06-26 11:59:27 - __main__ - INFO - error_handling_improvements.py:148 - Decorator result: None
2025-06-26 11:59:27 - __main__ - INFO - error_handling_improvements.py:69 - === ERROR RECOVERY STRATEGIES ===
2025-06-26 11:59:27 - __main__ - WARNING - error_handling_improvements.py:86 - Attempt 1 failed: Simulated network error. Retrying in 1s...
2025-06-26 11:59:28 - __main__ - WARNING - error_handling_improvements.py:86 - Attempt 2 failed: Simulated network error. Retrying in 2s...
2025-06-26 11:59:30 - __main__ - INFO - error_handling_improvements.py:80 - Operation succeeded on retry
2025-06-26 11:59:30 - __main__ - INFO - error_handling_improvements.py:153 - Recovery strategy result: True
2025-06-26 11:59:30 - __main__ - INFO - error_handling_improvements.py:97 - === CONTEXTUAL ERROR LOGGING ===
2025-06-26 11:59:30 - __main__ - ERROR - error_handling_improvements.py:111 - Chapter processing failed - Manga: Test Manga, Chapter: 001, Error: Invalid chapter data format
Traceback (most recent call last):
  File "F:\Documents\mangascraper1915\error_handling_improvements.py", line 107, in demonstrate_context_logging
    raise ValueError("Invalid chapter data format")
ValueError: Invalid chapter data format
2025-06-26 11:59:30 - __main__ - INFO - error_handling_improvements.py:118 - Skipping chapter 001 and continuing...
2025-06-26 11:59:30 - __main__ - INFO - error_handling_improvements.py:160 - Error handling demonstration completed successfully
2025-06-26 12:04:53 - quick_test - INFO - run_error_handling_tests.py:145 - Testing logging system...
2025-06-26 12:04:53 - quick_test - ERROR - logger.py:178 - Test operation: ValueError: Test error
Traceback (most recent call last):
  File "F:\Documents\mangascraper1915\utils\logger.py", line 195, in wrapper
    return func(*args, **kwargs)
           ^^^^^^^^^^^^^^^^^^^^^
  File "F:\Documents\mangascraper1915\run_error_handling_tests.py", line 160, in test_decorated_function
    raise ValueError("Test error")
ValueError: Test error
2025-06-26 12:05:03 - manga_scraper - INFO - config.py:144 - Configuration validated successfully for Webtoon Scraper v2.0.0
2025-06-26 12:05:03 - error_handling_tests - INFO - run_error_handling_tests.py:45 - Test environment setup completed
2025-06-26 12:05:04 - scraper.comment_analyzer - INFO - comment_analyzer.py:408 - NLTK data not found. Downloading required packages...
2025-06-26 12:05:05 - test_integration - WARNING - test_error_handling.py:440 - Advanced operation failed: Advanced feature not available. Falling back to simple method
2025-06-26 12:05:05 - test_recovery_integration - WARNING - test_error_scenarios.py:313 - Attempt 1 failed: Network failure
2025-06-26 12:05:05 - test_recovery_integration - WARNING - test_error_scenarios.py:313 - Attempt 2 failed: Database failure
2025-06-26 12:05:05 - test_recovery_integration - WARNING - test_error_scenarios.py:336 - Advanced feature failed, trying intermediate
2025-06-26 12:05:05 - test_recovery_integration - WARNING - test_error_scenarios.py:340 - Intermediate feature failed, using basic
2025-06-26 12:05:51 - manga_scraper - INFO - config.py:144 - Configuration validated successfully for Webtoon Scraper v2.0.0
2025-06-26 12:05:51 - error_handling_tests - INFO - run_error_handling_tests.py:45 - Test environment setup completed
2025-06-26 12:05:52 - scraper.comment_analyzer - INFO - comment_analyzer.py:408 - NLTK data not found. Downloading required packages...
2025-06-26 12:05:52 - test_integration - WARNING - test_error_handling.py:446 - Advanced operation failed: Advanced feature not available. Falling back to simple method
2025-06-26 12:05:53 - test_recovery_integration - WARNING - test_error_scenarios.py:326 - Attempt 1 failed: Network failure
2025-06-26 12:05:53 - test_recovery_integration - WARNING - test_error_scenarios.py:326 - Attempt 2 failed: Database failure
2025-06-26 12:05:53 - test_recovery_integration - WARNING - test_error_scenarios.py:349 - Advanced feature failed, trying intermediate
2025-06-26 12:05:53 - test_recovery_integration - WARNING - test_error_scenarios.py:353 - Intermediate feature failed, using basic
2025-06-26 12:06:45 - __main__ - INFO - demo_error_handling.py:132 - 🚀 Starting error handling demonstration...
2025-06-26 12:06:45 - __main__ - INFO - demo_error_handling.py:111 - 🎯 Demonstrating custom exception handling...
2025-06-26 12:06:45 - __main__ - ERROR - logger.py:178 - Handling NetworkError: NetworkError: API rate limit exceeded
Traceback (most recent call last):
  File "F:\Documents\mangascraper1915\demo_error_handling.py", line 122, in demonstrate_custom_exceptions
    raise exc
utils.logger.NetworkError: API rate limit exceeded
2025-06-26 12:06:45 - __main__ - ERROR - logger.py:178 - Handling DatabaseError: DatabaseError: Connection string invalid
Traceback (most recent call last):
  File "F:\Documents\mangascraper1915\demo_error_handling.py", line 122, in demonstrate_custom_exceptions
    raise exc
utils.logger.DatabaseError: Connection string invalid
2025-06-26 12:06:45 - __main__ - ERROR - logger.py:178 - Handling ParsingError: ParsingError: HTML structure changed - expected element not found
Traceback (most recent call last):
  File "F:\Documents\mangascraper1915\demo_error_handling.py", line 122, in demonstrate_custom_exceptions
    raise exc
utils.logger.ParsingError: HTML structure changed - expected element not found
2025-06-26 12:06:45 - __main__ - ERROR - logger.py:178 - Handling ValidationError: ValidationError: Chapter number must be positive integer
Traceback (most recent call last):
  File "F:\Documents\mangascraper1915\demo_error_handling.py", line 122, in demonstrate_custom_exceptions
    raise exc
utils.logger.ValidationError: Chapter number must be positive integer
2025-06-26 12:06:45 - __main__ - INFO - demo_error_handling.py:60 - 🔄 Demonstrating retry logic with exponential backoff...
2025-06-26 12:06:45 - __main__ - INFO - demo_error_handling.py:67 - Attempt 1/4
2025-06-26 12:06:45 - __main__ - ERROR - logger.py:178 - Network operation simulation: NetworkError: Connection timeout after 12 seconds
Traceback (most recent call last):
  File "F:\Documents\mangascraper1915\utils\logger.py", line 195, in wrapper
    return func(*args, **kwargs)
           ^^^^^^^^^^^^^^^^^^^^^
  File "F:\Documents\mangascraper1915\demo_error_handling.py", line 36, in simulate_network_operation
    raise NetworkError(f"Connection timeout after {random.randint(5, 15)} seconds")
utils.logger.NetworkError: Connection timeout after 12 seconds
2025-06-26 12:06:45 - __main__ - INFO - demo_error_handling.py:67 - Attempt 2/4
2025-06-26 12:06:45 - __main__ - INFO - demo_error_handling.py:38 - ✅ Network operation completed successfully
2025-06-26 12:06:45 - __main__ - INFO - demo_error_handling.py:70 - 🎉 Operation succeeded!
2025-06-26 12:06:45 - __main__ - INFO - demo_error_handling.py:141 - Retry demo result: {'status': 'success', 'data': 'sample_data'}
2025-06-26 12:06:45 - __main__ - INFO - demo_error_handling.py:85 - 🔧 Demonstrating graceful degradation...
2025-06-26 12:06:45 - __main__ - INFO - demo_error_handling.py:89 - Attempting advanced analysis...
2025-06-26 12:06:45 - __main__ - WARNING - demo_error_handling.py:94 - Advanced analysis failed: Advanced ML model not available
2025-06-26 12:06:45 - __main__ - INFO - demo_error_handling.py:98 - Falling back to intermediate analysis...
2025-06-26 12:06:45 - __main__ - INFO - demo_error_handling.py:146 - Graceful degradation result: intermediate_analysis_result
2025-06-26 12:06:45 - __main__ - INFO - demo_error_handling.py:150 - 🎭 Demonstrating decorator-based error handling...
2025-06-26 12:06:45 - __main__ - INFO - demo_error_handling.py:154 - Operation 1:
2025-06-26 12:06:45 - __main__ - ERROR - logger.py:178 - Network operation simulation: NetworkError: Connection timeout after 8 seconds
Traceback (most recent call last):
  File "F:\Documents\mangascraper1915\utils\logger.py", line 195, in wrapper
    return func(*args, **kwargs)
           ^^^^^^^^^^^^^^^^^^^^^
  File "F:\Documents\mangascraper1915\demo_error_handling.py", line 36, in simulate_network_operation
    raise NetworkError(f"Connection timeout after {random.randint(5, 15)} seconds")
utils.logger.NetworkError: Connection timeout after 8 seconds
2025-06-26 12:06:45 - __main__ - ERROR - logger.py:178 - Database operation simulation: DatabaseError: Disk full - cannot write to database
Traceback (most recent call last):
  File "F:\Documents\mangascraper1915\utils\logger.py", line 195, in wrapper
    return func(*args, **kwargs)
           ^^^^^^^^^^^^^^^^^^^^^
  File "F:\Documents\mangascraper1915\demo_error_handling.py", line 53, in simulate_database_operation
    raise scenario
utils.logger.DatabaseError: Disk full - cannot write to database
2025-06-26 12:06:45 - __main__ - INFO - demo_error_handling.py:154 - Operation 2:
2025-06-26 12:06:45 - __main__ - INFO - demo_error_handling.py:38 - ✅ Network operation completed successfully
2025-06-26 12:06:45 - __main__ - ERROR - logger.py:178 - Database operation simulation: DatabaseError: Table 'manga_chapters' doesn't exist
Traceback (most recent call last):
  File "F:\Documents\mangascraper1915\utils\logger.py", line 195, in wrapper
    return func(*args, **kwargs)
           ^^^^^^^^^^^^^^^^^^^^^
  File "F:\Documents\mangascraper1915\demo_error_handling.py", line 53, in simulate_database_operation
    raise scenario
utils.logger.DatabaseError: Table 'manga_chapters' doesn't exist
2025-06-26 12:06:45 - __main__ - INFO - demo_error_handling.py:159 -   Network: {'status': 'success', 'data': 'sample_data'}
2025-06-26 12:06:45 - __main__ - INFO - demo_error_handling.py:154 - Operation 3:
2025-06-26 12:06:45 - __main__ - ERROR - logger.py:178 - Network operation simulation: NetworkError: Connection timeout after 15 seconds
Traceback (most recent call last):
  File "F:\Documents\mangascraper1915\utils\logger.py", line 195, in wrapper
    return func(*args, **kwargs)
           ^^^^^^^^^^^^^^^^^^^^^
  File "F:\Documents\mangascraper1915\demo_error_handling.py", line 36, in simulate_network_operation
    raise NetworkError(f"Connection timeout after {random.randint(5, 15)} seconds")
utils.logger.NetworkError: Connection timeout after 15 seconds
2025-06-26 12:06:45 - __main__ - ERROR - logger.py:178 - Database operation simulation: DatabaseError: Connection pool exhausted
Traceback (most recent call last):
  File "F:\Documents\mangascraper1915\utils\logger.py", line 195, in wrapper
    return func(*args, **kwargs)
           ^^^^^^^^^^^^^^^^^^^^^
  File "F:\Documents\mangascraper1915\demo_error_handling.py", line 53, in simulate_database_operation
    raise scenario
utils.logger.DatabaseError: Connection pool exhausted
2025-06-26 12:06:45 - __main__ - INFO - demo_error_handling.py:164 - ✨ Demonstration completed!
